[2024-06-27T15:18:55.984+0000] {local_task_job_runner.py:120} INFO - ::group::Pre task execution logs
[2024-06-27T15:18:56.026+0000] {taskinstance.py:2076} INFO - Dependencies all met for dep_context=non-requeueable deps ti=<TaskInstance: rocket_launches_dag.get_pictures manual__2024-06-27T15:05:30.472820+00:00 [queued]>
[2024-06-27T15:18:56.037+0000] {taskinstance.py:2076} INFO - Dependencies all met for dep_context=requeueable deps ti=<TaskInstance: rocket_launches_dag.get_pictures manual__2024-06-27T15:05:30.472820+00:00 [queued]>
[2024-06-27T15:18:56.038+0000] {taskinstance.py:2306} INFO - Starting attempt 2 of 6
[2024-06-27T15:18:56.055+0000] {taskinstance.py:2330} INFO - Executing <Task(PythonOperator): get_pictures> on 2024-06-27 15:05:30.472820+00:00
[2024-06-27T15:18:56.062+0000] {warnings.py:112} WARNING - /home/***/.local/lib/python3.12/site-packages/***/task/task_runner/standard_task_runner.py:61: DeprecationWarning: This process (pid=489) is multi-threaded, use of fork() may lead to deadlocks in the child.
  pid = os.fork()

[2024-06-27T15:18:56.064+0000] {standard_task_runner.py:63} INFO - Started process 490 to run task
[2024-06-27T15:18:56.064+0000] {standard_task_runner.py:90} INFO - Running: ['***', 'tasks', 'run', 'rocket_launches_dag', 'get_pictures', 'manual__2024-06-27T15:05:30.472820+00:00', '--job-id', '47', '--raw', '--subdir', 'DAGS_FOLDER/rocket_launches_dag.py', '--cfg-path', '/tmp/tmpzzcy6_go']
[2024-06-27T15:18:56.065+0000] {standard_task_runner.py:91} INFO - Job 47: Subtask get_pictures
[2024-06-27T15:18:56.100+0000] {task_command.py:426} INFO - Running <TaskInstance: rocket_launches_dag.get_pictures manual__2024-06-27T15:05:30.472820+00:00 [running]> on host 69160e04a996
[2024-06-27T15:18:56.180+0000] {taskinstance.py:2648} INFO - Exporting env vars: AIRFLOW_CTX_DAG_OWNER='rocket_launches_dag' AIRFLOW_CTX_DAG_ID='rocket_launches_dag' AIRFLOW_CTX_TASK_ID='get_pictures' AIRFLOW_CTX_EXECUTION_DATE='2024-06-27T15:05:30.472820+00:00' AIRFLOW_CTX_TRY_NUMBER='2' AIRFLOW_CTX_DAG_RUN_ID='manual__2024-06-27T15:05:30.472820+00:00'
[2024-06-27T15:18:56.181+0000] {taskinstance.py:430} INFO - ::endgroup::
[2024-06-27T15:19:08.557+0000] {logging_mixin.py:188} INFO - Downloaded https://spacelaunchnow-prod-east.nyc3.digitaloceanspaces.com/media/images/falcon2520925_image_20221009234147.png to /tmp/images/falcon2520925_image_20221009234147.png
[2024-06-27T15:19:37.251+0000] {logging_mixin.py:188} INFO - Downloaded https://spacelaunchnow-prod-east.nyc3.digitaloceanspaces.com/media/images/falcon_9_on_slc_image_20240522073317.jpg to /tmp/images/falcon_9_on_slc_image_20240522073317.jpg
[2024-06-27T15:20:10.479+0000] {logging_mixin.py:188} INFO - Downloaded https://spacelaunchnow-prod-east.nyc3.digitaloceanspaces.com/media/images/long_march_7a_image_20210311201838.jpg to /tmp/images/long_march_7a_image_20210311201838.jpg
[2024-06-27T15:20:25.780+0000] {logging_mixin.py:188} INFO - Downloaded https://spacelaunchnow-prod-east.nyc3.digitaloceanspaces.com/media/images/ceres-1s_image_20230905114324.jpeg to /tmp/images/ceres-1s_image_20230905114324.jpeg
[2024-06-27T15:20:33.024+0000] {logging_mixin.py:188} INFO - Downloaded https://spacelaunchnow-prod-east.nyc3.digitaloceanspaces.com/media/images/h3-22_image_20230307130808.jpeg to /tmp/images/h3-22_image_20230307130808.jpeg
[2024-06-27T15:20:38.154+0000] {logging_mixin.py:188} INFO - Downloaded https://spacelaunchnow-prod-east.nyc3.digitaloceanspaces.com/media/images/firefly_alpha_l_image_20240605174156.jpeg to /tmp/images/firefly_alpha_l_image_20240605174156.jpeg
[2024-06-27T15:20:44.299+0000] {logging_mixin.py:188} INFO - Downloaded https://spacelaunchnow-prod-east.nyc3.digitaloceanspaces.com/media/images/falcon2520925_image_20221009234147.png to /tmp/images/falcon2520925_image_20221009234147.png
[2024-06-27T15:20:53.019+0000] {logging_mixin.py:188} INFO - Downloaded https://spacelaunchnow-prod-east.nyc3.digitaloceanspaces.com/media/images/long_march_6a_image_20221109174525.png to /tmp/images/long_march_6a_image_20221109174525.png
[2024-06-27T15:21:27.296+0000] {logging_mixin.py:188} INFO - Downloaded https://spacelaunchnow-prod-east.nyc3.digitaloceanspaces.com/media/images/falcon_9_image_20230807133459.jpeg to /tmp/images/falcon_9_image_20230807133459.jpeg
[2024-06-27T15:21:37.832+0000] {taskinstance.py:441} INFO - ::group::Post task execution logs
[2024-06-27T15:21:38.326+0000] {taskinstance.py:2905} ERROR - Task failed with exception
Traceback (most recent call last):
  File "/home/airflow/.local/lib/python3.12/site-packages/urllib3/connection.py", line 198, in _new_conn
    sock = connection.create_connection(
           ^^^^^^^^^^^^^^^^^^^^^^^^^^^^^
  File "/home/airflow/.local/lib/python3.12/site-packages/urllib3/util/connection.py", line 60, in create_connection
    for res in socket.getaddrinfo(host, port, family, socket.SOCK_STREAM):
               ^^^^^^^^^^^^^^^^^^^^^^^^^^^^^^^^^^^^^^^^^^^^^^^^^^^^^^^^^^
  File "/usr/local/lib/python3.12/socket.py", line 964, in getaddrinfo
    for res in _socket.getaddrinfo(host, port, family, type, proto, flags):
               ^^^^^^^^^^^^^^^^^^^^^^^^^^^^^^^^^^^^^^^^^^^^^^^^^^^^^^^^^^^
socket.gaierror: [Errno -3] Temporary failure in name resolution

The above exception was the direct cause of the following exception:

Traceback (most recent call last):
  File "/home/airflow/.local/lib/python3.12/site-packages/urllib3/connectionpool.py", line 793, in urlopen
    response = self._make_request(
               ^^^^^^^^^^^^^^^^^^^
  File "/home/airflow/.local/lib/python3.12/site-packages/urllib3/connectionpool.py", line 491, in _make_request
    raise new_e
  File "/home/airflow/.local/lib/python3.12/site-packages/urllib3/connectionpool.py", line 467, in _make_request
    self._validate_conn(conn)
  File "/home/airflow/.local/lib/python3.12/site-packages/urllib3/connectionpool.py", line 1099, in _validate_conn
    conn.connect()
  File "/home/airflow/.local/lib/python3.12/site-packages/urllib3/connection.py", line 616, in connect
    self.sock = sock = self._new_conn()
                       ^^^^^^^^^^^^^^^^
  File "/home/airflow/.local/lib/python3.12/site-packages/urllib3/connection.py", line 205, in _new_conn
    raise NameResolutionError(self.host, self, e) from e
urllib3.exceptions.NameResolutionError: <urllib3.connection.HTTPSConnection object at 0x7f5dfbe84590>: Failed to resolve 'spacelaunchnow-prod-east.nyc3.digitaloceanspaces.com' ([Errno -3] Temporary failure in name resolution)

The above exception was the direct cause of the following exception:

Traceback (most recent call last):
  File "/home/airflow/.local/lib/python3.12/site-packages/requests/adapters.py", line 486, in send
    resp = conn.urlopen(
           ^^^^^^^^^^^^^
  File "/home/airflow/.local/lib/python3.12/site-packages/urllib3/connectionpool.py", line 847, in urlopen
    retries = retries.increment(
              ^^^^^^^^^^^^^^^^^^
  File "/home/airflow/.local/lib/python3.12/site-packages/urllib3/util/retry.py", line 515, in increment
    raise MaxRetryError(_pool, url, reason) from reason  # type: ignore[arg-type]
    ^^^^^^^^^^^^^^^^^^^^^^^^^^^^^^^^^^^^^^^^^^^^^^^^^^^
urllib3.exceptions.MaxRetryError: HTTPSConnectionPool(host='spacelaunchnow-prod-east.nyc3.digitaloceanspaces.com', port=443): Max retries exceeded with url: /media/images/ariane252062_image_20190224012339.jpeg (Caused by NameResolutionError("<urllib3.connection.HTTPSConnection object at 0x7f5dfbe84590>: Failed to resolve 'spacelaunchnow-prod-east.nyc3.digitaloceanspaces.com' ([Errno -3] Temporary failure in name resolution)"))

During handling of the above exception, another exception occurred:

Traceback (most recent call last):
  File "/home/airflow/.local/lib/python3.12/site-packages/airflow/models/taskinstance.py", line 465, in _execute_task
    result = _execute_callable(context=context, **execute_callable_kwargs)
             ^^^^^^^^^^^^^^^^^^^^^^^^^^^^^^^^^^^^^^^^^^^^^^^^^^^^^^^^^^^^^
  File "/home/airflow/.local/lib/python3.12/site-packages/airflow/models/taskinstance.py", line 432, in _execute_callable
    return execute_callable(context=context, **execute_callable_kwargs)
           ^^^^^^^^^^^^^^^^^^^^^^^^^^^^^^^^^^^^^^^^^^^^^^^^^^^^^^^^^^^^
  File "/home/airflow/.local/lib/python3.12/site-packages/airflow/models/baseoperator.py", line 401, in wrapper
    return func(self, *args, **kwargs)
           ^^^^^^^^^^^^^^^^^^^^^^^^^^^
  File "/home/airflow/.local/lib/python3.12/site-packages/airflow/operators/python.py", line 235, in execute
    return_value = self.execute_callable()
                   ^^^^^^^^^^^^^^^^^^^^^^^
  File "/home/airflow/.local/lib/python3.12/site-packages/airflow/operators/python.py", line 252, in execute_callable
    return self.python_callable(*self.op_args, **self.op_kwargs)
           ^^^^^^^^^^^^^^^^^^^^^^^^^^^^^^^^^^^^^^^^^^^^^^^^^^^^^
  File "/opt/airflow/dags/rocket_launches_dag.py", line 23, in _get_pictures
    response = requests.get(image_url)
               ^^^^^^^^^^^^^^^^^^^^^^^
  File "/home/airflow/.local/lib/python3.12/site-packages/requests/api.py", line 73, in get
    return request("get", url, params=params, **kwargs)
           ^^^^^^^^^^^^^^^^^^^^^^^^^^^^^^^^^^^^^^^^^^^^
  File "/home/airflow/.local/lib/python3.12/site-packages/requests/api.py", line 59, in request
    return session.request(method=method, url=url, **kwargs)
           ^^^^^^^^^^^^^^^^^^^^^^^^^^^^^^^^^^^^^^^^^^^^^^^^^
  File "/home/airflow/.local/lib/python3.12/site-packages/requests/sessions.py", line 589, in request
    resp = self.send(prep, **send_kwargs)
           ^^^^^^^^^^^^^^^^^^^^^^^^^^^^^^
  File "/home/airflow/.local/lib/python3.12/site-packages/requests/sessions.py", line 703, in send
    r = adapter.send(request, **kwargs)
        ^^^^^^^^^^^^^^^^^^^^^^^^^^^^^^^
  File "/home/airflow/.local/lib/python3.12/site-packages/requests/adapters.py", line 519, in send
    raise ConnectionError(e, request=request)
requests.exceptions.ConnectionError: HTTPSConnectionPool(host='spacelaunchnow-prod-east.nyc3.digitaloceanspaces.com', port=443): Max retries exceeded with url: /media/images/ariane252062_image_20190224012339.jpeg (Caused by NameResolutionError("<urllib3.connection.HTTPSConnection object at 0x7f5dfbe84590>: Failed to resolve 'spacelaunchnow-prod-east.nyc3.digitaloceanspaces.com' ([Errno -3] Temporary failure in name resolution)"))
[2024-06-27T15:22:17.390+0000] {standard_task_runner.py:110} ERROR - Failed to execute job 47 for task get_pictures ((MySQLdb.OperationalError) (2005, "Unknown server host 'mysql' (-3)")
(Background on this error at: https://sqlalche.me/e/14/e3q8); 490)
[2024-06-27T15:22:24.934+0000] {local_task_job_runner.py:240} INFO - Task exited with return code 1
[2024-06-27T15:22:25.035+0000] {taskinstance.py:3503} INFO - 0 downstream tasks scheduled from follow-on schedule check
[2024-06-27T15:22:25.039+0000] {local_task_job_runner.py:222} INFO - ::endgroup::
